<?xml version="1.0" encoding="utf-8"?>
<!-- This URDF was automatically created by SolidWorks to URDF Exporter! Originally created by Stephen Brawner (brawner@gmail.com) 
     Commit Version: 1.6.0-4-g7f85cfe  Build Version: 1.6.7995.38578
     For more information, please see http://wiki.ros.org/sw_urdf_exporter -->
<robot
  name="mos_leg_51">
  <link
    name="hip_motor">
    <inertial>
      <origin
        xyz="0.0194551261869284 -0.0930459309938858 -0.146452078309495"
        rpy="0 0 0" />
      <mass
        value="0.193691933258787" />
      <inertia
        ixx="0.000212643438550045"
        ixy="2.52842936395237E-08"
        ixz="-3.06353262610855E-08"
        iyy="0.000111361590772374"
        iyz="-3.62933690347635E-07"
        izz="0.000115174940649883" />
    </inertial>
    <visual>
      <origin
        xyz="0 0 0"
        rpy="0 0 0" />
      <geometry>
        <mesh
          filename="package://mos_leg_51/meshes/hip_motor.STL" />
      </geometry>
      <material
        name="">
        <color
          rgba="1 1 1 1" />
      </material>
    </visual>
    <collision>
      <origin
        xyz="0 0 0"
        rpy="0 0 0" />
      <geometry>
        <mesh
          filename="package://mos_leg_51/meshes/hip_motor.STL" />
      </geometry>
    </collision>
  </link>
  <link
    name="hip_body">
    <inertial>
      <origin
        xyz="0.113371883083303 -0.00893173409426973 -0.000142723342939549"
        rpy="0 0 0" />
      <mass
        value="0.994407565035888" />
      <inertia
        ixx="0.000920741947553529"
        ixy="5.9477504341373E-08"
        ixz="-1.41358307769493E-07"
        iyy="0.00266050233065782"
        iyz="-3.88325839121468E-07"
        izz="0.00208351372160783" />
    </inertial>
    <visual>
      <origin
        xyz="0 0 0"
        rpy="0 0 0" />
      <geometry>
        <mesh
          filename="package://mos_leg_51/meshes/hip_body.STL" />
      </geometry>
      <material
        name="">
        <color
          rgba="1 1 1 1" />
      </material>
    </visual>
    <collision>
      <origin
        xyz="0 0 0"
        rpy="0 0 0" />
      <geometry>
        <mesh
          filename="package://mos_leg_51/meshes/hip_body.STL" />
      </geometry>
    </collision>
  </link>
  <joint
    name="hip_joint"
    type="revolute">
    <origin
      xyz="-0.232 -0.0931137748892989 -0.146354954727982"
      rpy="0 0 0" />
    <parent
      link="hip_motor" />
    <child
      link="hip_body" />
    <axis
      xyz="-1 0 0" />
    <limit
      lower="-0.5"
      upper="0.5"
      effort="30"
      velocity="3" />
  </joint>
  <link
    name="front_gear">
    <inertial>
      <origin
        xyz="-8.18928258539131E-14 -0.0390538870170614 8.06854583146333E-14"
        rpy="0 0 0" />
      <mass
        value="0.0385237466196057" />
      <inertia
        ixx="9.47389810508479E-06"
        ixy="7.56492562337561E-22"
        ixz="7.62880244624107E-22"
        iyy="1.02723402754827E-05"
        iyz="1.44092350357328E-21"
        izz="9.47389810508481E-06" />
    </inertial>
    <visual>
      <origin
        xyz="0 0 0"
        rpy="0 0 0" />
      <geometry>
        <mesh
          filename="package://mos_leg_51/meshes/front_gear.STL" />
      </geometry>
      <material
        name="">
        <color
          rgba="0.776470588235294 0.756862745098039 0.737254901960784 1" />
      </material>
    </visual>
    <collision>
      <origin
        xyz="0 0 0"
        rpy="0 0 0" />
      <geometry>
        <mesh
          filename="package://mos_leg_51/meshes/front_gear.STL" />
      </geometry>
    </collision>
  </link>
  <joint
    name="font_gear"
    type="revolute">
    <origin
      xyz="0.166000000000082 0.0461500000000458 0"
      rpy="0 0 0" />
    <parent
      link="hip_body" />
    <child
      link="front_gear" />
    <axis
      xyz="0 1 0" />
    <limit
      lower="-0.5"
      upper="0.5"
      effort="0"
      velocity="0" />
  </joint>
  <link
    name="rear_gear">
    <inertial>
      <origin
        xyz="2.77555756156289E-17 -0.0303984035950163 1.78468351208494E-14"
        rpy="0 0 0" />
      <mass
        value="0.0482357390578153" />
      <inertia
        ixx="1.0744281957417E-05"
        ixy="3.84649778803174E-21"
        ixz="4.92430958410474E-21"
        iyy="1.25106445892168E-05"
        iyz="1.01686787577547E-21"
        izz="1.0744281957417E-05" />
    </inertial>
    <visual>
      <origin
        xyz="0 0 0"
        rpy="0 0 0" />
      <geometry>
        <mesh
          filename="package://mos_leg_51/meshes/rear_gear.STL" />
      </geometry>
      <material
        name="">
        <color
          rgba="0.792156862745098 0.819607843137255 0.933333333333333 1" />
      </material>
    </visual>
    <collision>
      <origin
        xyz="0 0 0"
        rpy="0 0 0" />
      <geometry>
        <mesh
          filename="package://mos_leg_51/meshes/rear_gear.STL" />
      </geometry>
    </collision>
  </link>
  <joint
    name="rear_gear"
    type="revolute">
    <origin
      xyz="0.0659999999999999 0.0461499999999995 0"
      rpy="0 0 0" />
    <parent
      link="hip_body" />
    <child
      link="rear_gear" />
    <axis
      xyz="0 1 0" />
    <limit
      lower="-0.5"
      upper="0.5"
      effort="0"
      velocity="0" />
  </joint>
  <link
    name="thigh">
    <inertial>
      <origin
        xyz="-0.0334363727266302 -0.00646320958539248 -0.03378325831794"
        rpy="0 0 0" />
      <mass
        value="0.218415882803044" />
      <inertia
        ixx="0.000380276473573837"
        ixy="1.02303283100001E-05"
        ixz="-0.000289516209462419"
        iyy="0.000728917906995596"
        iyz="1.0336467359847E-05"
        izz="0.000374299610045337" />
    </inertial>
    <visual>
      <origin
        xyz="0 0 0"
        rpy="0 0 0" />
      <geometry>
        <mesh
          filename="package://mos_leg_51/meshes/thigh.STL" />
      </geometry>
      <material
        name="">
        <color
          rgba="1 1 1 1" />
      </material>
    </visual>
    <collision>
      <origin
        xyz="0 0 0"
        rpy="0 0 0" />
      <geometry>
        <mesh
          filename="package://mos_leg_51/meshes/thigh.STL" />
      </geometry>
    </collision>
  </link>
  <joint
    name="thigh_gear"
    type="revolute">
    <origin
      xyz="0.116 0.0681499999999996 -0.0101000000000015"
      rpy="0 0 0" />
    <parent
      link="hip_body" />
    <child
      link="thigh" />
    <axis
      xyz="0 -1 0" />
    <limit
      lower="-1"
      upper="1"
      effort="30"
      velocity="3" />
  </joint>
  <link
    name="shank">
    <inertial>
      <origin
        xyz="0.0501963925628425 -0.0140210751268604 -0.0375583634821985"
        rpy="0 0 0" />
      <mass
        value="0.286222361356515" />
      <inertia
        ixx="0.000651861312519635"
        ixy="-9.0760497068014E-07"
        ixz="0.00059808941560027"
        iyy="0.00130942075500998"
        iyz="8.16102370419575E-07"
        izz="0.000673127969335327" />
    </inertial>
    <visual>
      <origin
        xyz="0 0 0"
        rpy="0 0 0" />
      <geometry>
        <mesh
          filename="package://mos_leg_51/meshes/shank.STL" />
      </geometry>
      <material
        name="">
        <color
          rgba="0.792156862745098 0.819607843137255 0.933333333333333 1" />
      </material>
    </visual>
    <collision>
      <origin
        xyz="0 0 0"
        rpy="0 0 0" />
      <geometry>
        <mesh
          filename="package://mos_leg_51/meshes/shank.STL" />
      </geometry>
    </collision>
  </link>
  <joint
    name="shank_middle"
    type="continuous">
    <origin
      xyz="-0.122804058893964 0.0174955906880937 -0.131164562029674"
      rpy="0 0 0" />
    <parent
      link="thigh" />
    <child
      link="shank" />
    <axis
      xyz="0 -1 0" />
  </joint>
  <link
    name="shank_gear">
    <inertial>
      <origin
        xyz="-0.0305539081874436 -0.0151800390635338 0.031163163347574"
        rpy="0 0 0" />
      <mass
        value="0.171587734867676" />
      <inertia
        ixx="0.000249660019311512"
        ixy="4.99779954636461E-06"
        ixz="0.000197761556978693"
        iyy="0.000443409187193007"
        iyz="-5.08968268380674E-06"
        izz="0.000243414619824575" />
    </inertial>
    <visual>
      <origin
        xyz="0 0 0"
        rpy="0 0 0" />
      <geometry>
        <mesh
          filename="package://mos_leg_51/meshes/shank_gear.STL" />
      </geometry>
      <material
        name="">
        <color
          rgba="1 1 1 1" />
      </material>
    </visual>
    <collision>
      <origin
        xyz="0 0 0"
        rpy="0 0 0" />
      <geometry>
        <mesh
          filename="package://mos_leg_51/meshes/shank_gear.STL" />
      </geometry>
    </collision>
  </link>
  <joint
    name="shank_gear"
    type="revolute">
    <origin
      xyz="0.116 0.0871499999999995 -0.0100999999999999"
      rpy="0 0 0" />
    <parent
      link="hip_body" />
    <child
      link="shank_gear" />
    <axis
      xyz="0 1 0" />
    <limit
      lower="-1"
      upper="1"
      effort="30"
      velocity="3" />
  </joint>
  <link
    name="shank_link">
    <inertial>
      <origin
        xyz="-0.0443711312726666 -0.0128234647134589 -0.0571719050658158"
        rpy="0 0 0" />
      <mass
        value="0.0469428664864403" />
      <inertia
        ixx="9.71589752923396E-05"
        ixy="-3.64701280979714E-07"
        ixz="-5.79918854974176E-05"
        iyy="0.000135916178701613"
        iyz="-4.70048453048716E-07"
        izz="3.99674340455091E-05" />
    </inertial>
    <visual>
      <origin
        xyz="0 0 0"
        rpy="0 0 0" />
      <geometry>
        <mesh
          filename="package://mos_leg_51/meshes/shank_link.STL" />
      </geometry>
      <material
        name="">
        <color
          rgba="1 1 1 1" />
      </material>
    </visual>
    <collision>
      <origin
        xyz="0 0 0"
        rpy="0 0 0" />
      <geometry>
        <mesh
          filename="package://mos_leg_51/meshes/shank_link.STL" />
      </geometry>
    </collision>
  </link>
  <joint
    name="shank_link"
    type="continuous">
    <origin
      xyz="-0.109650305919864 -0.0060044093119062 0.111496767865736"
      rpy="0 0 0" />
    <parent
      link="shank_gear" />
    <child
      link="shank_link" />
    <axis
      xyz="0 1 0" />
  </joint>
</robot>