<?xml version="1.0" encoding="utf-8"?>
<!-- This URDF was automatically created by SolidWorks to URDF Exporter! Originally created by Stephen Brawner (brawner@gmail.com) 
     Commit Version: 1.6.0-4-g7f85cfe  Build Version: 1.6.7995.38578
     For more information, please see http://wiki.ros.org/sw_urdf_exporter -->
<robot
  name="mos_leg52">
  <link
    name="hip_motor">
    <inertial>
      <origin
        xyz="0.0194551261869284 -0.0930459309938858 -0.146452078309495"
        rpy="0 0 0" />
      <mass
        value="0.193691933258788" />
      <inertia
        ixx="0.000212643438550046"
        ixy="2.52842936395281E-08"
        ixz="-3.06353262610582E-08"
        iyy="0.000111361590772375"
        iyz="-3.62933690347613E-07"
        izz="0.000115174940649883" />
    </inertial>
    <visual>
      <origin
        xyz="0 0 0"
        rpy="0 0 0" />
      <geometry>
        <mesh
          filename="package://mos_leg52/meshes/hip_motor.STL" />
      </geometry>
      <material
        name="">
        <color
          rgba="1 1 1 1" />
      </material>
    </visual>
    <collision>
      <origin
        xyz="0 0 0"
        rpy="0 0 0" />
      <geometry>
        <mesh
          filename="package://mos_leg52/meshes/hip_motor.STL" />
      </geometry>
    </collision>
  </link>
  <link
    name="hip_body">
    <inertial>
      <origin
        xyz="0.113371883083302 -0.00893173409427045 -0.000142723342939716"
        rpy="0 0 0" />
      <mass
        value="0.994407565035914" />
      <inertia
        ixx="0.000920741947553536"
        ixy="5.94775043380676E-08"
        ixz="-1.41358307758304E-07"
        iyy="0.00266050233065784"
        iyz="-3.88325839119094E-07"
        izz="0.00208351372160785" />
    </inertial>
    <visual>
      <origin
        xyz="0 0 0"
        rpy="0 0 0" />
      <geometry>
        <mesh
          filename="package://mos_leg52/meshes/hip_body.STL" />
      </geometry>
      <material
        name="">
        <color
          rgba="1 1 1 1" />
      </material>
    </visual>
    <collision>
      <origin
        xyz="0 0 0"
        rpy="0 0 0" />
      <geometry>
        <mesh
          filename="package://mos_leg52/meshes/hip_body.STL" />
      </geometry>
    </collision>
  </link>
  <joint
    name="hip_joint"
    type="revolute">
    <origin
      xyz="-0.232 -0.093114 -0.14635"
      rpy="0 0 0" />
    <parent
      link="hip_motor" />
    <child
      link="hip_body" />
    <axis
      xyz="-1 0 0" />
    <limit
      lower="-0.5"
      upper="0.5"
      effort="30"
      velocity="3" />
  </joint>
  <link
    name="front_gear">
    <inertial>
      <origin
        xyz="-8.19205814295287E-14 -0.0390538870170614 7.99638133486269E-14"
        rpy="0 0 0" />
      <mass
        value="0.0385237466196058" />
      <inertia
        ixx="9.47389810508479E-06"
        ixy="7.24105232570262E-22"
        ixz="1.58246759764786E-21"
        iyy="1.02723402754827E-05"
        iyz="1.41942209438922E-21"
        izz="9.47389810508481E-06" />
    </inertial>
    <visual>
      <origin
        xyz="0 0 0"
        rpy="0 0 0" />
      <geometry>
        <mesh
          filename="package://mos_leg52/meshes/front_gear.STL" />
      </geometry>
      <material
        name="">
        <color
          rgba="0.776470588235294 0.756862745098039 0.737254901960784 1" />
      </material>
    </visual>
    <collision>
      <origin
        xyz="0 0 0"
        rpy="0 0 0" />
      <geometry>
        <mesh
          filename="package://mos_leg52/meshes/front_gear.STL" />
      </geometry>
    </collision>
  </link>
  <joint
    name="font_gear"
    type="revolute">
    <origin
      xyz="0.166 0.04615 0"
      rpy="0 0 0" />
    <parent
      link="hip_body" />
    <child
      link="front_gear" />
    <axis
      xyz="0 1 0" />
    <limit
      lower="-0.5"
      upper="0.5"
      effort="0"
      velocity="0" />
  </joint>
  <link
    name="rear_gear">
    <inertial>
      <origin
        xyz="-1.11022302462516E-15 -0.0303984035950163 1.79856129989275E-14"
        rpy="0 0 0" />
      <mass
        value="0.0482357390578153" />
      <inertia
        ixx="1.0744281957417E-05"
        ixy="2.99541972605816E-21"
        ixz="5.71319065723848E-21"
        iyy="1.25106445892168E-05"
        iyz="8.50480753893855E-22"
        izz="1.0744281957417E-05" />
    </inertial>
    <visual>
      <origin
        xyz="0 0 0"
        rpy="0 0 0" />
      <geometry>
        <mesh
          filename="package://mos_leg52/meshes/rear_gear.STL" />
      </geometry>
      <material
        name="">
        <color
          rgba="0.792156862745098 0.819607843137255 0.933333333333333 1" />
      </material>
    </visual>
    <collision>
      <origin
        xyz="0 0 0"
        rpy="0 0 0" />
      <geometry>
        <mesh
          filename="package://mos_leg52/meshes/rear_gear.STL" />
      </geometry>
    </collision>
  </link>
  <joint
    name="rear_gear"
    type="revolute">
    <origin
      xyz="0.066 0.04615 0"
      rpy="0 0 0" />
    <parent
      link="hip_body" />
    <child
      link="rear_gear" />
    <axis
      xyz="0 1 0" />
    <limit
      lower="-0.5"
      upper="0.5"
      effort="0"
      velocity="0" />
  </joint>
  <link
    name="thigh">
    <inertial>
      <origin
        xyz="-0.0334363727266321 -0.00646320958539248 -0.0337832583179401"
        rpy="0 0 0" />
      <mass
        value="0.218415882803044" />
      <inertia
        ixx="0.000380276473573837"
        ixy="1.02303283100001E-05"
        ixz="-0.000289516209462419"
        iyy="0.000728917906995597"
        iyz="1.03364673598469E-05"
        izz="0.000374299610045337" />
    </inertial>
    <visual>
      <origin
        xyz="0 0 0"
        rpy="0 0 0" />
      <geometry>
        <mesh
          filename="package://mos_leg52/meshes/thigh.STL" />
      </geometry>
      <material
        name="">
        <color
          rgba="1 1 1 1" />
      </material>
    </visual>
    <collision>
      <origin
        xyz="0 0 0"
        rpy="0 0 0" />
      <geometry>
        <mesh
          filename="package://mos_leg52/meshes/thigh.STL" />
      </geometry>
    </collision>
  </link>
  <joint
    name="thigh_gear"
    type="revolute">
    <origin
      xyz="0.116 0.06815 -0.0101"
      rpy="0 0 0" />
    <parent
      link="hip_body" />
    <child
      link="thigh" />
    <axis
      xyz="0 -1 0" />
    <limit
      lower="-1"
      upper="1"
      effort="30"
      velocity="3" />
  </joint>
  <link
    name="shank">
    <inertial>
      <origin
        xyz="0.0501963925591364 -0.014021075126307 -0.0375583634802569"
        rpy="0 0 0" />
      <mass
        value="0.286222361372181" />
      <inertia
        ixx="0.000651861312520624"
        ixy="-9.07604969125879E-07"
        ixz="0.000598089415604459"
        iyy="0.00130942075503528"
        iyz="8.1610237014393E-07"
        izz="0.00067312796935984" />
    </inertial>
    <visual>
      <origin
        xyz="0 0 0"
        rpy="0 0 0" />
      <geometry>
        <mesh
          filename="package://mos_leg52/meshes/shank.STL" />
      </geometry>
      <material
        name="">
        <color
          rgba="0.792156862745098 0.819607843137255 0.933333333333333 1" />
      </material>
    </visual>
    <collision>
      <origin
        xyz="0 0 0"
        rpy="0 0 0" />
      <geometry>
        <mesh
          filename="package://mos_leg52/meshes/shank.STL" />
      </geometry>
    </collision>
  </link>
  <joint
    name="shank_middle"
    type="continuous">
    <origin
      xyz="-0.1228 0.017496 -0.13116"
      rpy="0 0 0" />
    <parent
      link="thigh" />
    <child
      link="shank" />
    <axis
      xyz="0 -1 0" />
  </joint>
  <link
    name="shank_gear">
    <inertial>
      <origin
        xyz="-0.0305539081874453 -0.0151800390635337 0.031163163347574"
        rpy="0 0 0" />
      <mass
        value="0.171587734867677" />
      <inertia
        ixx="0.000249660019311512"
        ixy="4.99779954636463E-06"
        ixz="0.000197761556978693"
        iyy="0.000443409187193008"
        iyz="-5.08968268380678E-06"
        izz="0.000243414619824575" />
    </inertial>
    <visual>
      <origin
        xyz="0 0 0"
        rpy="0 0 0" />
      <geometry>
        <mesh
          filename="package://mos_leg52/meshes/shank_gear.STL" />
      </geometry>
      <material
        name="">
        <color
          rgba="1 1 1 1" />
      </material>
    </visual>
    <collision>
      <origin
        xyz="0 0 0"
        rpy="0 0 0" />
      <geometry>
        <mesh
          filename="package://mos_leg52/meshes/shank_gear.STL" />
      </geometry>
    </collision>
  </link>
  <joint
    name="shank_gear"
    type="revolute">
    <origin
      xyz="0.116 0.08715 -0.0101"
      rpy="0 0 0" />
    <parent
      link="hip_body" />
    <child
      link="shank_gear" />
    <axis
      xyz="0 1 0" />
    <limit
      lower="-1"
      upper="1"
      effort="30"
      velocity="3" />
  </joint>
  <link
    name="shank_link">
    <inertial>
      <origin
        xyz="-0.0443711312726687 -0.0128234647134589 -0.0571719050658156"
        rpy="0 0 0" />
      <mass
        value="0.0469428664864404" />
      <inertia
        ixx="9.71589752924468E-05"
        ixy="-3.64701280979704E-07"
        ixz="-5.7991885497864E-05"
        iyy="0.000135916178702011"
        iyz="-4.70048453048693E-07"
        izz="3.99674340458002E-05" />
    </inertial>
    <visual>
      <origin
        xyz="0 0 0"
        rpy="0 0 0" />
      <geometry>
        <mesh
          filename="package://mos_leg52/meshes/shank_link.STL" />
      </geometry>
      <material
        name="">
        <color
          rgba="1 1 1 1" />
      </material>
    </visual>
    <collision>
      <origin
        xyz="0 0 0"
        rpy="0 0 0" />
      <geometry>
        <mesh
          filename="package://mos_leg52/meshes/shank_link.STL" />
      </geometry>
    </collision>
  </link>
  <joint
    name="shank_link"
    type="continuous">
    <origin
      xyz="-0.10965 -0.0060044 0.1115"
      rpy="0 0 0" />
    <parent
      link="shank_gear" />
    <child
      link="shank_link" />
    <axis
      xyz="0 1 0" />
  </joint>
</robot>